Workbook

Sheet RFQ
L2: PENALTIES APPLY TO THIS ORDER
L3: NO PENALTIES APPLICABLE TO THIS ORDER
A9: RFQ No: | B9: =TRIM(LEFT(SUBSTITUTE(MID(CELL("filename",A2),FIND("[",CELL("filename",A2))+1,10),".xl",REPT(" ",255)),10)) -> AFRI-02A-1
A10: Description: | B10: =TRIM(LEFT(SUBSTITUTE(MID(CELL("filename",A1),FIND("[",CELL("filename",A1))+12,255),".xl",REPT(" ",255)),255)) -> 69-02-01 Manhours and Material
A11: Issued: | B11: =TODAY() -> 46315
A12: Closing: | B12: =B11+4 -> 46319
A14: ITEM | B14: DESCRIPTION | C14: UNITS | D14: QTY | E14: UNIT PRICE | F14: SUBTOTAL
A15: 1 | B15: 1. Straight pipe spool 6 Inch 6M | C15: PC | D15: 18 | E15: =IFERROR(VLOOKUP(B15,'Manpower Rate'!A$3:B$40,2,FALSE),0) -> 0 | F15: =E15*D15 -> 0
A16: 2 | B16: 150NB Pipe Sch 40 6M | C16: PC | D16: 18 | E16: =507*6 -> 3042 | F16: =E16*D16 -> 54756
A17: 3 | B17: 150NB Flanges | C17: PC | D17: =18*2 -> 36 | E17: 373.87 | F17: =E17*D17 -> 13459.32
A18: 4 | B18: Ceramic Lining | C18: PC | D18: 18 | E18: =14080*0.93 -> 13094.4 | F18: =E18*D18 -> 235699.2
A19: 5 | B19: Boiler Maker | C19: HRS | D19: 9 | E19: =IFERROR(VLOOKUP(B19,'Manpower Rate'!A$3:B$40,2,FALSE),0) -> 300 | F19: =E19*D19 -> 2700
A20: 6 | B20: General Assistants | C20: HRS | D20: 18 | E20: =IFERROR(VLOOKUP(B20,'Manpower Rate'!A$3:B$40,2,FALSE),0) -> 150 | F20: =E20*D20 -> 2700
A21: 7 | B21: Welder | C21: HRS | D21: 9 | E21: =IFERROR(VLOOKUP(B21,'Manpower Rate'!A$3:B$40,2,FALSE),0) -> 400 | F21: =E21*D21 -> 3600
A22: 8 | B22: Painter | C22: HRS | D22: 8 | E22: =IFERROR(VLOOKUP(B22,'Manpower Rate'!A$3:B$40,2,FALSE),0) -> 250 | F22: =E22*D22 -> 2000
A23: 9 | B23: Mechanical Engineer | C23: HRS | D23: 0.5 | E23: =IFERROR(VLOOKUP(B23,'Manpower Rate'!A$3:B$40,2,FALSE),0) -> 600 | F23: =E23*D23 -> 300
A24: 10 | B24: Procurement Officer | C24: HRS | D24: 0.5 | E24: =IFERROR(VLOOKUP(B24,'Manpower Rate'!A$3:B$40,2,FALSE),0) -> 300 | F24: =E24*D24 -> 150
A25: 11 | B25: Finance Clerk Intern | C25: HRS | D25: 0.5 | E25: =IFERROR(VLOOKUP(B25,'Manpower Rate'!A$3:B$40,2,FALSE),0) -> 150 | F25: =E25*D25 -> 75 | G25: =SUM(F16:F25) -> 315439.52
A26: 12 | E26: =IFERROR(VLOOKUP(B26,'Manpower Rate'!A$3:B$40,2,FALSE),0) -> 0 | F26: =E26*D26 -> 0
A27: 13 | B27: 2. Pipe bend/ offset assembly 2258mm & 2050mm 90 deg | C27: PC | D27: 16 | E27: =IFERROR(VLOOKUP(B27,'Manpower Rate'!A$3:B$40,2,FALSE),0) -> 0
A28: 14 | B28: 150NB Pipe Sch 40 6M | C28: PC | D28: 8 | E28: =507*6 -> 3042 | F28: =E28*D28 -> 24336 | H28: =2*437.23+2*462.88+2*451.56 -> 2703.34 | I28: mm
A29: 15 | B29: 150NB Flanges | C29: PC | D29: =16*2 -> 32 | E29: 373.87 | F29: =E29*D29 -> 11963.84 | H29: =H28*D27 -> 43253.44 | I29: mm
A30: 16 | B30: Ceramic Lining | C30: PC | D30: 16 | E30: =6900*0.93 -> 6417 | F30: =E30*D30 -> 102672
A31: 17 | B31: Boiler Maker | C31: HRS | D31: 16 | E31: =IFERROR(VLOOKUP(B31,'Manpower Rate'!A$3:B$40,2,FALSE),0) -> 300 | F31: =E31*D31 -> 4800
A32: 18 | B32: General Assistants | C32: HRS | D32: 16 | E32: =IFERROR(VLOOKUP(B32,'Manpower Rate'!A$3:B$40,2,FALSE),0) -> 150 | F32: =E32*D32 -> 2400
A33: 19 | B33: Welder | C33: HRS | D33: 16 | E33: =IFERROR(VLOOKUP(B33,'Manpower Rate'!A$3:B$40,2,FALSE),0) -> 400 | F33: =E33*D33 -> 6400
A34: 20 | B34: Painter | C34: HRS | D34: 8 | E34: =IFERROR(VLOOKUP(B34,'Manpower Rate'!A$3:B$40,2,FALSE),0) -> 250 | F34: =E34*D34 -> 2000
A35: 21 | B35: Mechanical Engineer | C35: HRS | D35: 2 | E35: =IFERROR(VLOOKUP(B35,'Manpower Rate'!A$3:B$40,2,FALSE),0) -> 600 | F35: =E35*D35 -> 1200
A36: 22 | B36: Procurement Officer | C36: HRS | D36: 0.5 | E36: =IFERROR(VLOOKUP(B36,'Manpower Rate'!A$3:B$40,2,FALSE),0) -> 300 | F36: =E36*D36 -> 150
A37: 23 | B37: Finance Clerk Intern | C37: HRS | D37: 0.5 | E37: =IFERROR(VLOOKUP(B37,'Manpower Rate'!A$3:B$40,2,FALSE),0) -> 150 | F37: =E37*D37 -> 75 | G37: =SUM(F28:F37) -> 155996.84
A38: 24 | B38: 3. Pipe bend/ support assembly 760mm span, 885mm run | C38: PC | D38: 4 | E38: =IFERROR(VLOOKUP(B38,'Manpower Rate'!A$3:B$40,2,FALSE),0) -> 0 | F38: =E38*D38 -> 0
A39: 25 | B39: 150NB Pipe Sch 40 6M | C39: PC | D39: 1 | E39: =507*6 -> 3042 | F39: =E39*D39 -> 3042 | H39: =740+2*128 -> 996 | I39: mm
A40: 26 | B40: 150NB Flanges | C40: PC | D40: 8 | E40: 373.87 | F40: =E40*D40 -> 2990.96 | H40: =H39*D38 -> 3984 | I40: mm
A41: 27 | B41: Ceramic Lining | C41: PC | D41: 4 | E41: =2200*0.93 -> 2046 | F41: =E41*D41 -> 8184
A42: 28 | B42: Boiler Maker | C42: HRS | D42: 4 | E42: =IFERROR(VLOOKUP(B42,'Manpower Rate'!A$3:B$40,2,FALSE),0) -> 300 | F42: =E42*D42 -> 1200
A43: 29 | B43: General Assistants | C43: HRS | D43: 4 | E43: =IFERROR(VLOOKUP(B43,'Manpower Rate'!A$3:B$40,2,FALSE),0) -> 150 | F43: =E43*D43 -> 600
A44: 30 | B44: Welder | C44: HRS | D44: 4 | E44: =IFERROR(VLOOKUP(B44,'Manpower Rate'!A$3:B$40,2,FALSE),0) -> 400 | F44: =E44*D44 -> 1600
A45: 31 | B45: Painter | C45: HRS | D45: 2 | E45: =IFERROR(VLOOKUP(B45,'Manpower Rate'!A$3:B$40,2,FALSE),0) -> 250 | F45: =E45*D45 -> 500
A46: 32 | B46: Mechanical Engineer | C46: HRS | D46: 2 | E46: =IFERROR(VLOOKUP(B46,'Manpower Rate'!A$3:B$40,2,FALSE),0) -> 600 | F46: =E46*D46 -> 1200
A47: 33 | B47: Procurement Officer | C47: HRS | D47: 0.5 | E47: =IFERROR(VLOOKUP(B47,'Manpower Rate'!A$3:B$40,2,FALSE),0) -> 300 | F47: =E47*D47 -> 150
...

Sheet Manpower Rate
A1: Time Based Rates | D1: Workshop | E1: Rate | F1: Office (Support) | G1: Rate | H1: Office (Core) | I1: Rate
B2: Selling Rate | D2: Snr Artisan | E2: 400 | F2: Manager | G2: 800 | H2: Director | I2: 1800
A3: Director | B3: 1800 | D3: Artisan | E3: 300 | F3: Snr Professional | G3: 400 | H3: Engineer | I3: 600
A4: Manager | B4: 800 | D4: Jnr Artisan | E4: 250 | F4: Profesional | G4: 300 | H4: Jnr Engineer | I4: 400
A5: Supervisor | B5: 500 | D5: Semi Skilled | E5: 200 | F5: Jnr Professional | G5: 250
A6: Senior Boiler Maker | B6: 400 | D6: General Assistant | E6: 150 | F6: Admin | G6: 200
A7: Boiler Maker | B7: 300 | D7: Manager | E7: 1200 | F7: Internship | G7: 150
A8: Semi-Skilled BM | B8: 200 | D8: Snr Manager | E8: 1400
A9: Senior Welder | B9: 500
A10: Welder | B10: 400
A11: Junior Welder | B11: 250
A12: Senior Rigger | B12: 400
A13: Rigger | B13: 300
A14: Senior Turner and Fitter | B14: 400
A15: Machine Operator | B15: 300
A16: Junior Machine Operator | B16: 250
A17: General Assistants | B17: 150
A18: Painter | B18: 250
A19: Driver | B19: 150
A20: Turner | B20: 300
... A36: SHEQ Officer | B36: 300

Sheet Detailed
B1: MAN HOURS FOR MATTE BIN
A4: ITEM | B4: DESCRIPTION | C4: UNITS | D4: QTY | E4: MANNING | F4: Item
A6: 1. | B6: Spider to keep tank round | C6: HRS | D6: 2 | E6: B/Maker+ Assistant | F6: 1
A7: 2. | B7: Cut Angle iron to size | C7: HRS | D7: 2 | E7: B/Maker + Assistant | F7: 1
A8: 3. | B8: Tack Spider + flange on barrel | C8: HRS | D8: 3 | E8: B/Maker + Assistant | F8: 1
A9: 4. | B9: Chamfering Square to round (both) | C9: HRS | D9: 1 | E9: 2 Assistant | F9: 1
A10: 5. | B10: Join square to round together and straightnig joints | C10: HRS | D10: 3 | E10: B/Maker + Assistant | F10: 4
A11: 6. | B11: Join Barrel to square to round | C11: HRS | D11: 3 | E11: B/Maker +Assistant + Crane | F11: 4
A12: 7. | B12: Weld the join and grind flat outside | C12: HRS | D12: 3 | E12: Welder + assistant + Crane op | F12: 5
A13: 8. | B13: Mark lines for flanges and Gasket | C13: HRS | D13: 1 | E13: B/Maker + Assistant | F13: 3
A14: 9. | B14: Tacking both flanges and Gaskets | C14: HRS | D14: 3 | E14: B/Maker + Assistant | F14: 4
A15: 10. | B15: Put flange on square to round | C15: HRS | D15: 1 | E15: B/Maker + Assistant | F15: 4
A16: 11. | B16: 519 Barrel with flanges,sliders | C16: HRS | D16: 3 | E16: B/Maker + Assistant | F16: 4
A17: 12. | B17: Weld the whole Silo + bottom box | C17: HRS | D17: 8 | E17: Welder + assistant + Crane op | F17: 5
... A19: 14. | B19: Washing (Pickle Paste | C19: HRS | D19: 4 | E19: 2 Assistant +Crane operator | F19: 8
